Workbook

Sheet DASHBOARD
A1: SmartDoc — Master Implementation Tracker
A2: Production-hardening brief. MASTER holds the task data; every number here is a formula. Updated with tools/tracker/tracker.py. Last written 2026-10-13 17:19 (local time).
A4: Overall | E4: Next action (SESSION_STATE)
A5: Total tasks | B5: =COUNTIF(MASTER!$A$2:$A$2000,"?*") -> 217 | C5: Rows in MASTER | E5: Current Phase | F5: =IF(SESSION_STATE!$B$5="","",SESSION_STATE!$B$5) -> 3 — DOCX follow-ups (P2) — IN_PROGRESS
A6: Completed (DONE) | B6: =COUNTIF(MASTER!$G$2:$G$2000,"DONE") -> 188 | C6: Implemented + tested + verified, commit recorded | E6: Current Task | F6: =IF(SESSION_STATE!$B$6="","",SESSION_STATE!$B$6) -> REL-005 — CRITICAL: production storage settings missing; waiting for the owner's approval to add them and redeploy.
A7: Verified (VERIFIED + DONE) | B7: =COUNTIF(MASTER!$G$2:$G$2000,"VERIFIED")+B6 -> 188 | C7: Tests pass and evidence is recorded | E7: Last Completed | F7: =IF(SESSION_STATE!$B$7="","",SESSION_STATE!$B$7) -> REL-021 — E-mail off said plainly (ad60739); image keeps bodies under Vercel's limit (e94afca); pooler fix (2490e5d). Preview only.
A8: In progress | B8: =COUNTIF(MASTER!$G$2:$G$2000,"IN_PROGRESS")+COUNTIF(MASTER!$G$2:$G$2000,"IMPLEMENTED")+COUNTIF(MASTER!$G$2:$G$2000,"TESTING") -> 8 | C8: IN_PROGRESS + IMPLEMENTED + TESTING | E8: Last Verified | F8: =IF(SESSION_STATE!$B$8="","",SESSION_STATE!$B$8) -> REL-021/REL-006/REL-013 — backend 2588/11, Vitest 368, tsc, next build, Playwright 59/1 local; e-mail-off pages seen on a throwaway local server — PASS — 2026-10-13
A9: Blocked | B9: =COUNTIF(MASTER!$G$2:$G$2000,"BLOCKED") -> 5 | C9: Reason in MASTER Notes | E9: Next Task | F9: =IF(SESSION_STATE!$B$14="","",SESSION_STATE!$B$14) -> REL-003 — On the owner's approval: add the missing Production settings (storage first), redeploy, promote e94afca, check /api/ready and the logs.
A10: Failed | B10: =COUNTIF(MASTER!$G$2:$G$2000,"FAILED") -> 0 | C10: See Notes and CHANGE_LOG | E10: Next Command | F10: =IF(SESSION_STATE!$B$15="","",SESSION_STATE!$B$15)
A11: Deferred | B11: =COUNTIF(MASTER!$G$2:$G$2000,"DEFERRED") -> 2 | C11: Postponed on purpose; still counted as remaining | E11: Next Test | F11: =IF(SESSION_STATE!$B$16="","",SESSION_STATE!$B$16)
A12: Not started | B12: =COUNTIF(MASTER!$G$2:$G$2000,"NOT_STARTED") -> 14 | E12: Tests Passed | F12: =IF(SESSION_STATE!$B$11="","",SESSION_STATE!$B$11) -> backend 2588/11; Vitest 368; Playwright 59 (Chromium, local); next build; tsc
A13: Remaining (not DONE) | B13: =B5-B6 -> 29 | C13: Everything that is not DONE | E13: Tests Failed | F13: =IF(SESSION_STATE!$B$12="","",SESSION_STATE!$B$12) -> none
A14: Completion % | B14: =IF(B5=0,0,B6/B5) -> 0.86635945 | C14: DONE / total | E14: Open Blockers | F14: =IF(SESSION_STATE!$B$13="","",SESSION_STATE!$B$13) -> INFRA-010: no Docker on this machine; real deployment needs Boril's hosting target; GATE-004/013: CI's PostgreSQL job result; TEST-021A: the expected-loss-linux CI artifact must be downloaded and merged (python -m scripts.merge_expected_losses DIR)
A15: Verified % | B15: =IF(B5=0,0,B7/B5) -> 0.86635945 | C15: (VERIFIED + DONE) / total | E15: Checkpoint Time | F15: =IF(SESSION_STATE!$B$17="","",SESSION_STATE!$B$17) -> 2026-10-13T17:19:01+03:00
A16: P0 remaining | B16: =COUNTIFS(MASTER!$F$2:$F$2000,"P0",MASTER!$G$2:$G$2000,"<>DONE") -> 9 | C16: P0 tasks not DONE
A17: P1 remaining | B17: =COUNTIFS(MASTER!$F$2:$F$2000,"P1",MASTER!$G$2:$G$2000,"<>DONE") -> 8 | C17: P1 tasks not DONE | E17: Progress by phase
A18: Audit findings resolved | B18: =CRITICAL_FIXES!B4 -> 19 | C18: Of 20; see CRITICAL_FIXES | E18: Phase | F18: Name | G18: Tasks | H18: Done | I18: Verified | J18: In progress | K18: Blocked | L18: Failed | M18: Done % | N18: Verified %
A19: Release gates passed | B19: =RELEASE_GATES!B4 -> 13 | C19: Of 15; see RELEASE_GATES | E19: 0 | F19: Baseline, tracker, checkpoints | G19: =COUNTIF(MASTER!$B$2:$B$2000,$E19) -> 11 | H19: =COUNTIFS(MASTER!$B$2:$B$2000,$E19,MASTER!$G$2:$G$2000,"DONE") -> 11 | I19: =COUNTIFS(MASTER!$B$2:$B$2000,$E19,MASTER!$G$2:$G$2000,"VERIFIED")+H19 -> 11 | J19: =COUNTIFS(MASTER!$B$2:$B$2000,$E19,MASTER!$G$2:$G$2000,"IN_PROGRESS")+COUNTIFS(MASTER!$B$2:$B$2000,$E19,MASTER!$G$2:$G$2000,"IMPLEMENTED")+COUNTIFS(MASTER!$B$2:$B$2000,$E19,MASTER!$G$2:$G$2000,"TESTING") -> 0 | K19: =COUNTIFS(MASTER!$B$2:$B$2000,$E19,MASTER!$G$2:$G$2000,"BLOCKED") -> 0 | L19: =COUNTIFS(MASTER!$B$2:$B$2000,$E19,MASTER!$G$2:$G$2000,"FAILED") -> 0 | M19: =IF(G19=0,0,H19/G19) -> 1 | N19: =IF(G19=0,0,I19/G19) -> 1
A20: Release gates failed | B20: =RELEASE_GATES!C4 -> 0 | E20: 1 | F20: Editor integrity + content preservation | G20: =COUNTIF(MASTER!$B$2:$B$2000,$E20) -> 26 | H20: =COUNTIFS(MASTER!$B$2:$B$2000,$E20,MASTER!$G$2:$G$2000,"DONE") -> 26 | I20: =COUNTIFS(MASTER!$B$2:$B$2000,$E20,MASTER!$G$2:$G$2000,"VERIFIED")+H20 -> 26 | J20: =COUNTIFS(MASTER!$B$2:$B$2000,$E20,MASTER!$G$2:$G$2000,"IN_PROGRESS")+COUNTIFS(MASTER!$B$2:$B$2000,$E20,MASTER!$G$2:$G$2000,"IMPLEMENTED")+COUNTIFS(MASTER!$B$2:$B$2000,$E20,MASTER!$G$2:$G$2000,"TESTING") -> 0 | K20: =COUNTIFS(MASTER!$B$2:$B$2000,$E20,MASTER!$G$2:$G$2000,"BLOCKED") -> 0 | L20: =COUNTIFS(MASTER!$B$2:$B$2000,$E20,MASTER!$G$2:$G$2000,"FAILED") -> 0 | M20: =IF(G20=0,0,H20/G20) -> 1 | N20: =IF(G20=0,0,I20/G20) -> 1
E21: 2 | F21: AI fidelity + destructive-operation review | G21: =COUNTIF(MASTER!$B$2:$B$2000,$E21) -> 11 | H21: =COUNTIFS(MASTER!$B$2:$B$2000,$E21,MASTER!$G$2:$G$2000,"DONE") -> 10 | I21: =COUNTIFS(MASTER!$B$2:$B$2000,$E21,MASTER!$G$2:$G$2000,"VERIFIED")+H21 -> 10 | J21: =COUNTIFS(MASTER!$B$2:$B$2000,$E21,MASTER!$G$2:$G$2000,"IN_PROGRESS")+COUNTIFS(MASTER!$B$2:$B$2000,$E21,MASTER!$G$2:$G$2000,"IMPLEMENTED")+COUNTIFS(MASTER!$B$2:$B$2000,$E21,MASTER!$G$2:$G$2000,"TESTING") -> 0 | K21: =COUNTIFS(MASTER!$B$2:$B$2000,$E21,MASTER!$G$2:$G$2000,"BLOCKED") -> 0 | L21: =COUNTIFS(MASTER!$B$2:$B$2000,$E21,MASTER!$G$2:$G$2000,"FAILED") -> 0 | M21: =IF(G21=0,0,H21/G21) -> 0.90909091 | N21: =IF(G21=0,0,I21/G21) -> 0.90909091
A22: Tasks by status | E22: 3 | F22: DOCX / OOXML preservation | G22: =COUNTIF(MASTER!$B$2:$B$2000,$E22) -> 46 | H22: =COUNTIFS(MASTER!$B$2:$B$2000,$E22,MASTER!$G$2:$G$2000,"DONE") -> 44 | I22: =COUNTIFS(MASTER!$B$2:$B$2000,$E22,MASTER!$G$2:$G$2000,"VERIFIED")+H22 -> 44 | J22: =COUNTIFS(MASTER!$B$2:$B$2000,$E22,MASTER!$G$2:$G$2000,"IN_PROGRESS")+COUNTIFS(MASTER!$B$2:$B$2000,$E22,MASTER!$G$2:$G$2000,"IMPLEMENTED")+COUNTIFS(MASTER!$B$2:$B$2000,$E22,MASTER!$G$2:$G$2000,"TESTING") -> 0 | K22: =COUNTIFS(MASTER!$B$2:$B$2000,$E22,MASTER!$G$2:$G$2000,"BLOCKED") -> 1 | L22: =COUNTIFS(MASTER!$B$2:$B$2000,$E22,MASTER!$G$2:$G$2000,"FAILED") -> 0 | M22: =IF(G22=0,0,H22/G22) -> 0.95652174 | N22: =IF(G22=0,0,I22/G22) -> 0.95652174
A23: Status | B23: Tasks | C23: Meaning | E23: 4 | F23: Security + resource limits | G23: =COUNTIF(MASTER!$B$2:$B$2000,$E23) -> 15 | H23: =COUNTIFS(MASTER!$B$2:$B$2000,$E23,MASTER!$G$2:$G$2000,"DONE") -> 14 | I23: =COUNTIFS(MASTER!$B$2:$B$2000,$E23,MASTER!$G$2:$G$2000,"VERIFIED")+H23 -> 14 | J23: =COUNTIFS(MASTER!$B$2:$B$2000,$E23,MASTER!$G$2:$G$2000,"IN_PROGRESS")+COUNTIFS(MASTER!$B$2:$B$2000,$E23,MASTER!$G$2:$G$2000,"IMPLEMENTED")+COUNTIFS(MASTER!$B$2:$B$2000,$E23,MASTER!$G$2:$G$2000,"TESTING") -> 0 | K23: =COUNTIFS(MASTER!$B$2:$B$2000,$E23,MASTER!$G$2:$G$2000,"BLOCKED") -> 1 | L23: =COUNTIFS(MASTER!$B$2:$B$2000,$E23,MASTER!$G$2:$G$2000,"FAILED") -> 0 | M23: =IF(G23=0,0,H23/G23) -> 0.93333333 | N23: =IF(G23=0,0,I23/G23) -> 0.93333333
A24: NOT_STARTED | B24: =COUNTIF(MASTER!$G$2:$G$2000,A24) -> 14 | C24: No work yet. | E24: 5 | F24: Performance + autosave + history | G24: =COUNTIF(MASTER!$B$2:$B$2000,$E24) -> 11 | H24: =COUNTIFS(MASTER!$B$2:$B$2000,$E24,MASTER!$G$2:$G$2000,"DONE") -> 10 | I24: =COUNTIFS(MASTER!$B$2:$B$2000,$E24,MASTER!$G$2:$G$2000,"VERIFIED")+H24 -> 10 | J24: =COUNTIFS(MASTER!$B$2:$B$2000,$E24,MASTER!$G$2:$G$2000,"IN_PROGRESS")+COUNTIFS(MASTER!$B$2:$B$2000,$E24,MASTER!$G$2:$G$2000,"IMPLEMENTED")+COUNTIFS(MASTER!$B$2:$B$2000,$E24,MASTER!$G$2:$G$2000,"TESTING") -> 0 | K24: =COUNTIFS(MASTER!$B$2:$B$2000,$E24,MASTER!$G$2:$G$2000,"BLOCKED") -> 0 | L24: =COUNTIFS(MASTER!$B$2:$B$2000,$E24,MASTER!$G$2:$G$2000,"FAILED") -> 0 | M24: =IF(G24=0,0,H24/G24) -> 0.90909091 | N24: =IF(G24=0,0,I24/G24) -> 0.90909091
A25: IN_PROGRESS | B25: =COUNTIF(MASTER!$G$2:$G$2000,A25) -> 3 | C25: Being implemented. | E25: 6 | F25: Accounts + billing + entitlements | G25: =COUNTIF(MASTER!$B$2:$B$2000,$E25) -> 14 | H25: =COUNTIFS(MASTER!$B$2:$B$2000,$E25,MASTER!$G$2:$G$2000,"DONE") -> 14 | I25: =COUNTIFS(MASTER!$B$2:$B$2000,$E25,MASTER!$G$2:$G$2000,"VERIFIED")+H25 -> 14 | J25: =COUNTIFS(MASTER!$B$2:$B$2000,$E25,MASTER!$G$2:$G$2000,"IN_PROGRESS")+COUNTIFS(MASTER!$B$2:$B$2000,$E25,MASTER!$G$2:$G$2000,"IMPLEMENTED")+COUNTIFS(MASTER!$B$2:$B$2000,$E25,MASTER!$G$2:$G$2000,"TESTING") -> 0 | K25: =COUNTIFS(MASTER!$B$2:$B$2000,$E25,MASTER!$G$2:$G$2000,"BLOCKED") -> 0 | L25: =COUNTIFS(MASTER!$B$2:$B$2000,$E25,MASTER!$G$2:$G$2000,"FAILED") -> 0 | M25: =IF(G25=0,0,H25/G25) -> 1 | N25: =IF(G25=0,0,I25/G25) -> 1
A26: BLOCKED | B26: =COUNTIF(MASTER!$G$2:$G$2000,A26) -> 5 | C26: Cannot proceed; the reason is in Notes. | E26: 7 | F26: PDF fidelity foundation | G26: =COUNTIF(MASTER!$B$2:$B$2000,$E26) -> 3 | H26: =COUNTIFS(MASTER!$B$2:$B$2000,$E26,MASTER!$G$2:$G$2000,"DONE") -> 3 | I26: =COUNTIFS(MASTER!$B$2:$B$2000,$E26,MASTER!$G$2:$G$2000,"VERIFIED")+H26 -> 3 | J26: =COUNTIFS(MASTER!$B$2:$B$2000,$E26,MASTER!$G$2:$G$2000,"IN_PROGRESS")+COUNTIFS(MASTER!$B$2:$B$2000,$E26,MASTER!$G$2:$G$2000,"IMPLEMENTED")+COUNTIFS(MASTER!$B$2:$B$2000,$E26,MASTER!$G$2:$G$2000,"TESTING") -> 0 | K26: =COUNTIFS(MASTER!$B$2:$B$2000,$E26,MASTER!$G$2:$G$2000,"BLOCKED") -> 0 | L26: =COUNTIFS(MASTER!$B$2:$B$2000,$E26,MASTER!$G$2:$G$2000,"FAILED") -> 0 | M26: =IF(G26=0,0,H26/G26) -> 1 | N26: =IF(G26=0,0,I26/G26) -> 1
A27: IMPLEMENTED | B27: =COUNTIF(MASTER!$G$2:$G$2000,A27) -> 5 | C27: Code written; not yet fully tested. | E27: 8 | F27: PDF -> editable MVP | G27: =COUNTIF(MASTER!$B$2:$B$2000,$E27) -> 9 | H27: =COUNTIFS(MASTER!$B$2:$B$2000,$E27,MASTER!$G$2:$G$2000,"DONE") -> 9 | I27: =COUNTIFS(MASTER!$B$2:$B$2000,$E27,MASTER!$G$2:$G$2000,"VERIFIED")+H27 -> 9 | J27: =COUNTIFS(MASTER!$B$2:$B$2000,$E27,MASTER!$G$2:$G$2000,"IN_PROGRESS")+COUNTIFS(MASTER!$B$2:$B$2000,$E27,MASTER!$G$2:$G$2000,"IMPLEMENTED")+COUNTIFS(MASTER!$B$2:$B$2000,$E27,MASTER!$G$2:$G$2000,"TESTING") -> 0 | K27: =COUNTIFS(MASTER!$B$2:$B$2000,$E27,MASTER!$G$2:$G$2000,"BLOCKED") -> 0 | L27: =COUNTIFS(MASTER!$B$2:$B$2000,$E27,MASTER!$G$2:$G$2000,"FAILED") -> 0 | M27: =IF(G27=0,0,H27/G27) -> 1 | N27: =IF(G27=0,0,I27/G27) -> 1
A28: TESTING | B28: =COUNTIF(MASTER!$G$2:$G$2000,A28) -> 0 | C28: Tests being written or run. | E28: 9 | F28: PDF layout-preserving architecture | G28: =COUNTIF(MASTER!$B$2:$B$2000,$E28) -> 4 | H28: =COUNTIFS(MASTER!$B$2:$B$2000,$E28,MASTER!$G$2:$G$2000,"DONE") -> 3 | I28: =COUNTIFS(MASTER!$B$2:$B$2000,$E28,MASTER!$G$2:$G$2000,"VERIFIED")+H28 -> 3 | J28: =COUNTIFS(MASTER!$B$2:$B$2000,$E28,MASTER!$G$2:$G$2000,"IN_PROGRESS")+COUNTIFS(MASTER!$B$2:$B$2000,$E28,MASTER!$G$2:$G$2000,"IMPLEMENTED")+COUNTIFS(MASTER!$B$2:$B$2000,$E28,MASTER!$G$2:$G$2000,"TESTING") -> 0 | K28: =COUNTIFS(MASTER!$B$2:$B$2000,$E28,MASTER!$G$2:$G$2000,"BLOCKED") -> 0 | L28: =COUNTIFS(MASTER!$B$2:$B$2000,$E28,MASTER!$G$2:$G$2000,"FAILED") -> 0 | M28: =IF(G28=0,0,H28/G28) -> 0.75 | N28: =IF(G28=0,0,I28/G28) -> 0.75
A29: VERIFIED | B29: =COUNTIF(MASTER!$G$2:$G$2000,A29) -> 0 | C29: Tests pass and evidence recorded; commit pending. | E29: 10 | F29: Translation MVP | G29: =COUNTIF(MASTER!$B$2:$B$2000,$E29) -> 10 | H29: =COUNTIFS(MASTER!$B$2:$B$2000,$E29,MASTER!$G$2:$G$2000,"DONE") -> 10 | I29: =COUNTIFS(MASTER!$B$2:$B$2000,$E29,MASTER!$G$2:$G$2000,"VERIFIED")+H29 -> 10 | J29: =COUNTIFS(MASTER!$B$2:$B$2000,$E29,MASTER!$G$2:$G$2000,"IN_PROGRESS")+COUNTIFS(MASTER!$B$2:$B$2000,$E29,MASTER!$G$2:$G$2000,"IMPLEMENTED")+COUNTIFS(MASTER!$B$2:$B$2000,$E29,MASTER!$G$2:$G$2000,"TESTING") -> 0 | K29: =COUNTIFS(MASTER!$B$2:$B$2000,$E29,MASTER!$G$2:$G$2000,"BLOCKED") -> 0 | L29: =COUNTIFS(MASTER!$B$2:$B$2000,$E29,MASTER!$G$2:$G$2000,"FAILED") -> 0 | M29: =IF(G29=0,0,H29/G29) -> 1 | N29: =IF(G29=0,0,I29/G29) -> 1
A30: DONE | B30: =COUNTIF(MASTER!$G$2:$G$2000,A30) -> 188 | C30: Implemented + tested + verified; commit recorded. | E30: 11 | F30: FontResolver + multilingual rendering | G30: =COUNTIF(MASTER!$B$2:$B$2000,$E30) -> 6 | H30: =COUNTIFS(MASTER!$B$2:$B$2000,$E30,MASTER!$G$2:$G$2000,"DONE") -> 6 | I30: =COUNTIFS(MASTER!$B$2:$B$2000,$E30,MASTER!$G$2:$G$2000,"VERIFIED")+H30 -> 6 | J30: =COUNTIFS(MASTER!$B$2:$B$2000,$E30,MASTER!$G$2:$G$2000,"IN_PROGRESS")+COUNTIFS(MASTER!$B$2:$B$2000,$E30,MASTER!$G$2:$G$2000,"IMPLEMENTED")+COUNTIFS(MASTER!$B$2:$B$2000,$E30,MASTER!$G$2:$G$2000,"TESTING") -> 0 | K30: =COUNTIFS(MASTER!$B$2:$B$2000,$E30,MASTER!$G$2:$G$2000,"BLOCKED") -> 0 | L30: =COUNTIFS(MASTER!$B$2:$B$2000,$E30,MASTER!$G$2:$G$2000,"FAILED") -> 0 | M30: =IF(G30=0,0,H30/G30) -> 1 | N30: =IF(G30=0,0,I30/G30) -> 1
A31: FAILED | B31: =COUNTIF(MASTER!$G$2:$G$2000,A31) -> 0 | C31: Tests or verification failed; see Notes. | E31: 12 | F31: Format by Example hardening | G31: =COUNTIF(MASTER!$B$2:$B$2000,$E31) -> 4 | H31: =COUNTIFS(MASTER!$B$2:$B$2000,$E31,MASTER!$G$2:$G$2000,"DONE") -> 4 | I31: =COUNTIFS(MASTER!$B$2:$B$2000,$E31,MASTER!$G$2:$G$2000,"VERIFIED")+H31 -> 4 | J31: =COUNTIFS(MASTER!$B$2:$B$2000,$E31,MASTER!$G$2:$G$2000,"IN_PROGRESS")+COUNTIFS(MASTER!$B$2:$B$2000,$E31,MASTER!$G$2:$G$2000,"IMPLEMENTED")+COUNTIFS(MASTER!$B$2:$B$2000,$E31,MASTER!$G$2:$G$2000,"TESTING") -> 0 | K31: =COUNTIFS(MASTER!$B$2:$B$2000,$E31,MASTER!$G$2:$G$2000,"BLOCKED") -> 0 | L31: =COUNTIFS(MASTER!$B$2:$B$2000,$E31,MASTER!$G$2:$G$2000,"FAILED") -> 0 | M31: =IF(G31=0,0,H31/G31) -> 1 | N31: =IF(G31=0,0,I31/G31) -> 1
A32: DEFERRED | B32: =COUNTIF(MASTER!$G$2:$G$2000,A32) -> 2 | C32: Consciously postponed; the reason is in Notes. | E32: 13 | F32: Document Health 2.0 | G32: =COUNTIF(MASTER!$B$2:$B$2000,$E32) -> 3 | H32: =COUNTIFS(MASTER!$B$2:$B$2000,$E32,MASTER!$G$2:$G$2000,"DONE") -> 3 | I32: =COUNTIFS(MASTER!$B$2:$B$2000,$E32,MASTER!$G$2:$G$2000,"VERIFIED")+H32 -> 3 | J32: =COUNTIFS(MASTER!$B$2:$B$2000,$E32,MASTER!$G$2:$G$2000,"IN_PROGRESS")+COUNTIFS(MASTER!$B$2:$B$2000,$E32,MASTER!$G$2:$G$2000,"IMPLEMENTED")+COUNTIFS(MASTER!$B$2:$B$2000,$E32,MASTER!$G$2:$G$2000,"TESTING") -> 0 | K32: =COUNTIFS(MASTER!$B$2:$B$2000,$E32,MASTER!$G$2:$G$2000,"BLOCKED") -> 0 | L32: =COUNTIFS(MASTER!$B$2:$B$2000,$E32,MASTER!$G$2:$G$2000,"FAILED") -> 0 | M32: =IF(G32=0,0,H32/G32) -> 1 | N32: =IF(G32=0,0,I32/G32) -> 1
A33: UNKNOWN | B33: =COUNTIF(MASTER!$G$2:$G$2000,A33) -> 0 | C33: State not established yet. | E33: 14 | F33: Review Changes / Repair | G33: =COUNTIF(MASTER!$B$2:$B$2000,$E33) -> 4 | H33: =COUNTIFS(MASTER!$B$2:$B$2000,$E33,MASTER!$G$2:$G$2000,"DONE") -> 4 | I33: =COUNTIFS(MASTER!$B$2:$B$2000,$E33,MASTER!$G$2:$G$2000,"VERIFIED")+H33 -> 4 | J33: =COUNTIFS(MASTER!$B$2:$B$2000,$E33,MASTER!$G$2:$G$2000,"IN_PROGRESS")+COUNTIFS(MASTER!$B$2:$B$2000,$E33,MASTER!$G$2:$G$2000,"IMPLEMENTED")+COUNTIFS(MASTER!$B$2:$B$2000,$E33,MASTER!$G$2:$G$2000,"TESTING") -> 0 | K33: =COUNTIFS(MASTER!$B$2:$B$2000,$E33,MASTER!$G$2:$G$2000,"BLOCKED") -> 0 | L33: =COUNTIFS(MASTER!$B$2:$B$2000,$E33,MASTER!$G$2:$G$2000,"FAILED") -> 0 | M33: =IF(G33=0,0,H33/G33) -> 1 | N33: =IF(G33=0,0,I33/G33) -> 1
E34: 15 | F34: Batch operations | G34: =COUNTIF(MASTER!$B$2:$B$2000,$E34) -> 3 | H34: =COUNTIFS(MASTER!$B$2:$B$2000,$E34,MASTER!$G$2:$G$2000,"DONE") -> 3 | I34: =COUNTIFS(MASTER!$B$2:$B$2000,$E34,MASTER!$G$2:$G$2000,"VERIFIED")+H34 -> 3 | J34: =COUNTIFS(MASTER!$B$2:$B$2000,$E34,MASTER!$G$2:$G$2000,"IN_PROGRESS")+COUNTIFS(MASTER!$B$2:$B$2000,$E34,MASTER!$G$2:$G$2000,"IMPLEMENTED")+COUNTIFS(MASTER!$B$2:$B$2000,$E34,MASTER!$G$2:$G$2000,"TESTING") -> 0 | K34: =COUNTIFS(MASTER!$B$2:$B$2000,$E34,MASTER!$G$2:$G$2000,"BLOCKED") -> 0 | L34: =COUNTIFS(MASTER!$B$2:$B$2000,$E34,MASTER!$G$2:$G$2000,"FAILED") -> 0 | M34: =IF(G34=0,0,H34/G34) -> 1 | N34: =IF(G34=0,0,I34/G34) -> 1
A35: Latest test runs (TESTING) | E35: 16 | F35: Accessibility + advanced document features | G35: =COUNTIF(MASTER!$B$2:$B$2000,$E35) -> 5 | H35: =COUNTIFS(MASTER!$B$2:$B$2000,$E35,MASTER!$G$2:$G$2000,"DONE") -> 5 | I35: =COUNTIFS(MASTER!$B$2:$B$2000,$E35,MASTER!$G$2:$G$2000,"VERIFIED")+H35 -> 5 | J35: =COUNTIFS(MASTER!$B$2:$B$2000,$E35,MASTER!$G$2:$G$2000,"IN_PROGRESS")+COUNTIFS(MASTER!$B$2:$B$2000,$E35,MASTER!$G$2:$G$2000,"IMPLEMENTED")+COUNTIFS(MASTER!$B$2:$B$2000,$E35,MASTER!$G$2:$G$2000,"TESTING") -> 0 | K35: =COUNTIFS(MASTER!$B$2:$B$2000,$E35,MASTER!$G$2:$G$2000,"BLOCKED") -> 0 | L35: =COUNTIFS(MASTER!$B$2:$B$2000,$E35,MASTER!$G$2:$G$2000,"FAILED") -> 0 | M35: =IF(G35=0,0,H35/G35) -> 1 | N35: =IF(G35=0,0,I35/G35) -> 1
A36: Suite | B36: Result | C36: Passed · failed · skipped | E36: 17 | F36: Final testing | G36: =COUNTIF(MASTER!$B$2:$B$2000,$E36) -> 6 | H36: =COUNTIFS(MASTER!$B$2:$B$2000,$E36,MASTER!$G$2:$G$2000,"DONE") -> 4 | I36: =COUNTIFS(MASTER!$B$2:$B$2000,$E36,MASTER!$G$2:$G$2000,"VERIFIED")+H36 -> 4 | J36: =COUNTIFS(MASTER!$B$2:$B$2000,$E36,MASTER!$G$2:$G$2000,"IN_PROGRESS")+COUNTIFS(MASTER!$B$2:$B$2000,$E36,MASTER!$G$2:$G$2000,"IMPLEMENTED")+COUNTIFS(MASTER!$B$2:$B$2000,$E36,MASTER!$G$2:$G$2000,"TESTING") -> 1 | K36: =COUNTIFS(MASTER!$B$2:$B$2000,$E36,MASTER!$G$2:$G$2000,"BLOCKED") -> 1 | L36: =COUNTIFS(MASTER!$B$2:$B$2000,$E36,MASTER!$G$2:$G$2000,"FAILED") -> 0 | M36: =IF(G36=0,0,H36/G36) -> 0.66666667 | N36: =IF(G36=0,0,I36/G36) -> 0.66666667
A37: =TESTING!B314&" — "&TESTING!A314 -> e2e — RUN-0307 | B37: =TESTING!C314&"" -> PASS | C37: =TESTING!E314&" passed · "&TESTING!F314&" failed · "&TESTING!H314&" skipped" -> 59 passed · 0 failed · 1 skipped | E37: 18 | F37: Production release audit | G37: =COUNTIF(MASTER!$B$2:$B$2000,$E37) -> 2 | H37: =COUNTIFS(MASTER!$B$2:$B$2000,$E37,MASTER!$G$2:$G$2000,"DONE") -> 2 | I37: =COUNTIFS(MASTER!$B$2:$B$2000,$E37,MASTER!$G$2:$G$2000,"VERIFIED")+H37 -> 2 | J37: =COUNTIFS(MASTER!$B$2:$B$2000,$E37,MASTER!$G$2:$G$2000,"IN_PROGRESS")+COUNTIFS(MASTER!$B$2:$B$2000,$E37,MASTER!$G$2:$G$2000,"IMPLEMENTED")+COUNTIFS(MASTER!$B$2:$B$2000,$E37,MASTER!$G$2:$G$2000,"TESTING") -> 0 | K37: =COUNTIFS(MASTER!$B$2:$B$2000,$E37,MASTER!$G$2:$G$2000,"BLOCKED") -> 0 | L37: =COUNTIFS(MASTER!$B$2:$B$2000,$E37,MASTER!$G$2:$G$2000,"FAILED") -> 0 | M37: =IF(G37=0,0,H37/G37) -> 1 | N37: =IF(G37=0,0,I37/G37) -> 1
A38: =TESTING!B313&" — "&TESTING!A313 -> frontend — RUN-0306 | B38: =TESTING!C313&"" -> PASS | C38: =TESTING!E313&" passed · "&TESTING!F313&" failed · "&TESTING!H313&" skipped" -> 368 passed · 0 failed · 0 skipped | E38: 19 | F38: First public release (target 2026-10-15) | G38: =COUNTIF(MASTER!$B$2:$B$2000,$E38) -> 24 | H38: =COUNTIFS(MASTER!$B$2:$B$2000,$E38,MASTER!$G$2:$G$2000,"DONE") -> 3 | I38: =COUNTIFS(MASTER!$B$2:$B$2000,$E38,MASTER!$G$2:$G$2000,"VERIFIED")+H38 -> 3 | J38: =COUNTIFS(MASTER!$B$2:$B$2000,$E38,MASTER!$G$2:$G$2000,"IN_PROGRESS")+COUNTIFS(MASTER!$B$2:$B$2000,$E38,MASTER!$G$2:$G$2000,"IMPLEMENTED")+COUNTIFS(MASTER!$B$2:$B$2000,$E38,MASTER!$G$2:$G$2000,"TESTING") -> 7 | K38: =COUNTIFS(MASTER!$B$2:$B$2000,$E38,MASTER!$G$2:$G$2000,"BLOCKED") -> 2 | L38: =COUNTIFS(MASTER!$B$2:$B$2000,$E38,MASTER!$G$2:$G$2000,"FAILED") -> 0 | M38: =IF(G38=0,0,H38/G38) -> 0.125 | N38: =IF(G38=0,0,I38/G38) -> 0.125
A39: =TESTING!B312&" — "&TESTING!A312 -> backend — RUN-0305 | B39: =TESTING!C312&"" -> PASS | C39: =TESTING!E312&" passed · "&TESTING!F312&" failed · "&TESTING!H312&" skipped" -> 2588 passed · 0 failed · 11 skipped
A40: =TESTING!B311&" — "&TESTING!A311 -> backend — RUN-0304 | B40: =TESTING!C311&"" -> PASS | C40: =TESTING!E311&" passed · "&TESTING!F311&" failed · "&TESTING!H311&" skipped" -> 2578 passed · 0 failed · 11 skipped | E40: Progress by category
A41: =TESTING!B310&" — "&TESTING!A310 -> backend — RUN-0303 | B41: =TESTING!C310&"" -> PASS | C41: =TESTING!E310&" passed · "&TESTING!F310&" failed · "&TESTING!H310&" skipped" -> 2571 passed · 0 failed · 11 skipped | E41: Category | F41: Sheet | G41: Tasks | H41: Done | I41: Verified | J41: In progress | K41: Blocked | L41: Failed | M41: Done % | N41: Verified %
...

Sheet MASTER
A1: ID | B1: Phase | C1: Category | D1: Feature/Task | E1: Description | F1: Priority | G1: Status | H1: Evidence | I1: Tests | J1: Owner/System | K1: Dependencies | L1: Risk | M1: Started | N1: Completed | O1: Last Verified | P1: Commit | Q1: Notes | R1: Parent ID | S1: Audit Ref
A2: INFRA-001 | B2: 0 | C2: INFRA | D2: Excel control centre | E2: SmartDoc_Master_Implementation_Tracker.xlsx with MASTER, dashboard formulas, category views, conditional formatting, validation; tools/tracker CLI to update it. | F2: P0 | G2: DONE | H2: SmartDoc_Master_Implementation_Tracker.xlsx: 20 sheets (19 required + DASHBOARD), 3,340 formulas, status/priority/risk/category/phase validation, conditional formatting; tools/tracker/tracker.py, seed.py, excel_recalc.py, selftest.py, README.md | I2: python tools/tracker/selftest.py -> PASS; tools/tracker/excel_recalc.py -> 0 formula errors, 0 value mismatches (also on a scratch copy covering every status) | J2: tools/tracker | L2: Low | M2: 46292.161 | N2: 46292.171 | O2: 46292.171 | P2: 4da4ecb
A3: INFRA-002 | B3: 0 | C3: INFRA | D3: Continuation system | E3: docs/AI-CONTINUATION.md + docs/session-state.json kept current at every checkpoint. | F3: P0 | G3: DONE | H3: docs/AI-CONTINUATION.md (8 required sections), docs/session-state.json (all 19 fields of brief §11), SESSION_STATE sheet (14 fields of brief §110 + Excel Status), docs/implementation-brief.md | I3: tracker.py state --touch synced JSON -> SESSION_STATE and wrote current_excel_status back; selftest covers the state command | J3: docs | K3: INFRA-001 | L3: Low | M3: 46292.162 | N3: 46292.171 | O3: 46292.171 | P3: 4da4ecb
A4: INFRA-003 | B4: 0 | C4: INFRA | D4: Resume reminder | E4: Session scheduler job that resumes from docs/AI-CONTINUATION.md while idle. | F4: P1 | G4: DONE | H4: Session cron job 2a28a683 (hourly at :23, session-only, auto-expires after 7 days) with the resume prompt | I4: Fired on 2026-09-27 and resumed this session from the continuation prompt | J4: session | L4: Low | M4: 46292.161 | N4: 46292.171 | O4: 46292.171 | P4: 4da4ecb
A5: TEST-001 | B5: 0 | C5: TESTING | D5: Baseline: backend tests | E5: Full pytest run recorded (count, failures, duration, coverage). | F5: P0 | G5: DONE | H5: docs/architecture/current-baseline.md; TESTING RUN-0001 | I5: backend pytest: 643 passed, 1 skipped, 0 failed (88 s) | J5: backend/tests | L5: Low | M5: 46292.167 | N5: 46292.172 | O5: 46292.172 | P5: 4da4ecb
A6: TEST-002 | B6: 0 | C6: TESTING | D6: Baseline: frontend tests, typecheck, lint, build | E6: Vitest, tsc --noEmit, eslint, next build. | F6: P0 | G6: DONE | H6: docs/architecture/current-baseline.md; TESTING RUN-0002..0005 | I6: eslint 0 problems; tsc 0 errors; Vitest 46/46; next build OK (11 routes) | J6: frontend | L6: Low | M6: 46292.167 | N6: 46292.172 | O6: 46292.172 | P6: 4da4ecb
A7: TEST-003 | B7: 0 | C7: TESTING | D7: Baseline: Playwright E2E | E7: npm run test:e2e against the throwaway stack. | F7: P0 | G7: DONE | H7: docs/architecture/current-baseline.md; TESTING RUN-0006 | I7: Playwright (Edge): 16 passed, 0 failed (67 s) | J7: frontend/e2e | L7: Low | M7: 46292.167 | N7: 46292.172 | O7: 46292.172 | P7: 4da4ecb
A8: TEST-004 | B8: 0 | C8: TESTING | D8: Baseline: migrations and database | E8: alembic upgrade/check/downgrade/upgrade on scratch DB; offline Postgres SQL; Supabase migrations + advisors. | F8: P0 | G8: DONE | H8: docs/architecture/current-baseline.md; TESTING RUN-0007, RUN-0008 | I8: alembic upgrade/check/downgrade/upgrade on scratch SQLite; offline PostgreSQL SQL; Supabase list_migrations 8/8 + advisors | J8: backend/alembic | L8: Low | M8: 46292.167 | N8: 46292.172 | O8: 46292.172 | P8: 4da4ecb
A9: SEC-001 | B9: 0 | C9: SECURITY | D9: Baseline: dependency audit | E9: pip-audit on both locks; npm audit. | F9: P1 | G9: DONE | H9: docs/architecture/current-baseline.md; TESTING RUN-0009, RUN-0010 | I9: pip-audit (both locks): no known vulnerabilities; npm audit: 0 of 633 dependencies | J9: backend, frontend | L9: Low | M9: 46292.168 | N9: 46292.172 | O9: 46292.172 | P9: 4da4ecb
A10: INFRA-004 | B10: 0 | C10: INFRA | D10: Baseline: Docker, worker, storage | E10: docker compose config; Dockerfiles; arq worker; storage providers inspected. | F10: P1 | G10: DONE | H10: docs/architecture/current-baseline.md; TESTING RUN-0011 | I10: docker compose config --quiet (valid, 8 services); worker (arq app.worker.WorkerSettings) and storage (local / S3 providers) inspected | J10: docker, jobs, storage | L10: Low | M10: 46292.168 | N10: 46292.172 | O10: 46292.172 | P10: 4da4ecb | Q10: Images not built: Docker daemon not running here; image build + start is INFRA-010 (phase 17).
A11: TEST-005 | B11: 0 | C11: TESTING | D11: Baseline: fixture inventory | E11: Golden fixtures + the audit's Word-authored fixtures inventoried. | F11: P1 | G11: DONE | H11: docs/architecture/current-baseline.md (fixture inventory) | I11: backend/tests/fixtures: 12 generated DOCX + sample.pdf; 17 Word-authored audit fixtures (a01-a12, r01-r05) outside the repo | J11: backend/tests/fixtures | L11: Low | M11: 46292.168 | N11: 46292.172 | O11: 46292.172 | P11: 4da4ecb
A12: DOCS-001 | B12: 0 | C12: DOCS | D12: current-baseline.md | E12: docs/architecture/current-baseline.md with measured baseline. | F12: P0 | G12: DONE | H12: docs/architecture/current-baseline.md | I12: Every figure taken from RUN-0001..RUN-0011 logs, Supabase MCP output and the audit's perf logs | J12: docs | K12: TEST-001,TEST-002,TEST-003,TEST-004 | L12: Low | M12: 46292.168 | N12: 46292.172 | O12: 46292.172 | P12: 4da4ecb
A13: CORE-001 | B13: 1 | C13: CORE | D13: Nested block containers in the model | E13: TableCell.blocks, ListItem.blocks and Element.children (quotes) hold lists, code, images, quotes, nested tables; recursive, validated, backwards compatible. | F13: P0 | G13: DONE | H13: backend/app/models/document.py: TableCell.blocks, ListItem.blocks, Element.children, Element.numbering (ListNumbering start/format), MAX_BLOCK_DEPTH=8 validator, child_blocks/walk_elements/inline_runs | I13: tests/test_document_nesting.py (9); full backend 659 passed | J13: backend/models | L13: High | M13: 46292.176 | N13: 46292.196 | O13: 46292.196 | P13: 1fe27a9 | Q13: Design: TableCell.blocks / ListItem.blocks / Element.children hold nested Elements (authoritative when set; inline keeps the plain text); Element.numbering {start, format}; nesting capped at MAX_BLOCK_DEPTH; walk_elements() for every consumer. | S13: AUD-01,AUD-19
A14: CORE-002 | B14: 1 | C14: CORE | D14: OpenAPI + generated types for nested blocks | E14: Regenerate openapi.json and frontend types; contract test green. | F14: P0 | G14: DONE | H14: frontend/types/generated/openapi.json + api.ts regenerated; types/document.ts exports ListNumbering/NumberFormat | I14: tests/test_openapi_contract.py; npx tsc --noEmit clean | J14: backend/scripts, frontend/types | K14: CORE-001 | L14: Medium | M14: 46292.19 | N14: 46292.197 | O14: 46292.197 | P14: 1fe27a9 | R14: CORE-001 | S14: AUD-01
A15: CORE-003 | B15: 1 | C15: CORE | D15: Nested blocks through the backend | E15: Engine styles, asset externalisation, health, compare, version descriptions, usage/storage size traverse nested blocks. | F15: P0 | G15: DONE | H15: services/image_assets.py (nested data: images validated and stored, junk removed and reported), services/document_service.py export_assets (walk_elements), formatting/health.py links via inline_runs; asset cleanup already scans the whole JSON | I15: tests/test_nested_blocks_api.py (stored as sent, asset once, junk removed, depth 422); tests/test_health.py nested links | J15: backend/formatting, services | K15: CORE-001 | L15: High | M15: 46292.19 | N15: 46292.197 | O15: 46292.197 | P15: 1fe27a9 | R15: CORE-001 | S15: AUD-01
A16: EDIT-001 | B16: 1 | C16: EDITOR | D16: Map nested blocks inside table cells | E16: tiptapToDocument: lists, code, images, quotes, nested tables in cells saved (no silent discard). | F16: P0 | G16: DONE | H16: frontend/editor/tiptapToDocument.ts, documentToTiptap.ts | I16: frontend/editor/nestedBlocks.test.ts (28; 26 fail against the pre-fix mapping); e2e/nested.spec.ts (Edge: paste, autosave, reload) | J16: frontend/editor | K16: CORE-002 | L16: High | M16: 46292.19 | N16: 46292.197 | O16: 46292.197 | P16: 1fe27a9 | S16: AUD-01
A17: EDIT-002 | B17: 1 | C17: EDITOR | D17: Map blocks inside list items | E17: Code blocks, images, extra paragraphs inside list items saved. | F17: P0 | G17: DONE | H17: frontend/editor/tiptapToDocument.ts, documentToTiptap.ts | I17: frontend/editor/nestedBlocks.test.ts (28; 26 fail against the pre-fix mapping); e2e/nested.spec.ts (Edge: paste, autosave, reload) | J17: frontend/editor | K17: CORE-002 | L17: High | M17: 46292.19 | N17: 46292.197 | O17: 46292.197 | P17: 1fe27a9 | S17: AUD-01
A18: EDIT-003 | B18: 1 | C18: EDITOR | D18: Map blocks inside quotes | E18: Lists, code, images inside blockquotes saved. | F18: P0 | G18: DONE | H18: frontend/editor/tiptapToDocument.ts, documentToTiptap.ts | I18: frontend/editor/nestedBlocks.test.ts (28; 26 fail against the pre-fix mapping); e2e/nested.spec.ts (Edge: paste, autosave, reload) | J18: frontend/editor | K18: CORE-002 | L18: High | M18: 46292.19 | N18: 46292.197 | O18: 46292.197 | P18: 1fe27a9 | S18: AUD-01
A19: EDIT-004 | B19: 1 | C19: EDITOR | D19: Render nested blocks back into the editor | E19: documentToTiptap renders every nested block kind. | F19: P0 | G19: DONE | H19: frontend/editor/tiptapToDocument.ts, documentToTiptap.ts | I19: frontend/editor/nestedBlocks.test.ts (28; 26 fail against the pre-fix mapping); e2e/nested.spec.ts (Edge: paste, autosave, reload) | J19: frontend/editor | K19: EDIT-001,EDIT-002,EDIT-003 | L19: High | M19: 46292.19 | N19: 46292.197 | O19: 46292.197 | P19: 1fe27a9 | S19: AUD-01
A20: EDIT-005 | B20: 1 | C20: EDITOR | D20: Save guard: never drop a node silently | E20: Any node the mapping cannot represent blocks the save with an explicit, user-visible error. | F20: P0 | G20: DONE | H20: tiptapToDocument.ts UnsupportedContentError (unknown node/inline node/mark anywhere); useAutoSave 'unsupported' status (no request, message, beforeunload warning); EditorStatusBar message | I20: nestedBlocks.test.ts refusal cases + schema coverage; useAutoSave.test.tsx (no request, 'unsupported' status, message, saves again once fixed) | J20: frontend/editor | K20: EDIT-004 | L20: High | M20: 46292.19 | N20: 46292.197 | O20: 46292.197 | P20: 1fe27a9 | S20: AUD-01
A21: EDIT-008 | B21: 1 | C21: EDITOR | D21: Pasted paragraph/heading alignment kept | E21: textAlign on top-level paragraphs/headings (from pasted HTML) is not stored: the model keeps alignment as formatting rules. Map it to element overrides or report it. | F21: P1 | G21: DONE | H21: textAlign on top-level paragraphs/headings (paste, Mod-Shift-L/E/R/J, copied on split) is saved as the element's own alignment: reconcileWithIds returns DirectStyle entries only when it differs from the element's resolved alignment; PUT /content carries them (UpdateContentRequest.styles, validated, element override without a revision). documentToTiptap puts an element's own alignment on the block as textAlign so a split keeps it (as Word). Editor bug fixed: pasting into an empty paragraph poured the first pasted paragraph into it and dropped its alignment (pasteIntoEmptyBlock.ts). After each save the editor shows each block the look it was saved with (syncAppliedStyles). Nested alignment is named as not kept. | I21: frontend/editor/directFormatting.test.ts (9), frontend/editor/useAutoSave.test.tsx (+3), frontend/editor/editorRoundTrip.test.ts (+12: golden documents open with no direct styles/notes), frontend/e2e/direct-formatting.spec.ts, tests/test_editor_direct_styles.py (2); Vitest 109, Playwright 19, backend 749 | J21: frontend/editor | L21: Medium | M21: 46292.398 | N21: 46292.399 | O21: 46292.399 | P21: 53c84e4 | R21: EDIT-005 | S21: AUD-03
A22: EDIT-009 | B22: 1 | C22: EDITOR | D22: Pasted picture size kept | E22: Image node width/height (pasted or resized) are not stored; the model sizes pictures through IMAGE_WIDTH rules. | F22: P1 | G22: DONE | H22: A top-level picture's width attribute (pasted '321', '321px', '40%') becomes an IMAGE_WIDTH element override as a share of the text width (page width minus margins at 96 dpi, capped at 100%, one decimal); a width that can't be one is named; nested pictures' sizes are named as not kept. E2E: 321 px on A4 with 2 cm margins -> 50% after reload. | I22: frontend/editor/directFormatting.test.ts (picture size), frontend/e2e/direct-formatting.spec.ts, tests/test_editor_direct_styles.py | J22: frontend/editor | L22: Medium | M22: 46292.398 | N22: 46292.399 | O22: 46292.399 | P22: 53c84e4 | R22: EDIT-005 | S22: AUD-07
A23: EDIT-010 | B23: 1 | C23: EDITOR | D23: Link title kept | E23: A link's title (tooltip) is not stored in Mark; target/rel/class are the editor's own defaults. | F23: P2 | G23: DONE | H23: Mark.title (<=500) in the model and generated types; editor link title <-> Mark.title (one line, capped at 500 with a note); Word import from w:hyperlink/@w:tooltip and a HYPERLINK field's \o switch (simple and complex fields); Word export writes w:tooltip; Markdown [text](url "title") keeps it. PDF has no tooltips (matrix note). | I23: tests/test_link_titles.py (Word import/export round trip incl. field ScreenTip; Markdown), frontend/editor/directFormatting.test.ts (a link's title: 2) | J23: frontend/editor | L23: Low | M23: 46292.407 | N23: 46292.416 | O23: 46292.416 | P23: 66bbdf1 | R23: EDIT-005 | S23: AUD-01
A24: EDIT-011 | B24: 1 | C24: EDITOR | D24: Cell alignment and column widths kept | E24: tableCell align/colwidth attributes, and a cell alignment that differs from its column's, are not stored (TableContent.alignments is per column). | F24: P2 | G24: DONE | H24: Nothing about cells is lost silently any more: a pasted cell's own alignment (td align / style) counts for its column (kept when the column agrees); a cell aligned differently from its column and pasted column widths (<colgroup>/colwidth) are named by the editor as not kept (status bar + Проверка 'While editing'). Keeping per-cell alignment and column widths needs model fields (TableCell alignment, TableContent column widths) with Word/PDF export and Word import - moved to DOCX-017 (table engine), recorded there. | I24: frontend/editor/directFormatting.test.ts::tables | J24: frontend/editor | L24: Low | M24: 46292.398 | N24: 46292.416 | O24: 46292.416 | P24: 66bbdf1 | Q24: Done: a pasted cell's own alignment (td align / style) counts for its column; cells aligned differently from their column and column widths (pasted <colgroup>) are named as not kept. Remaining: keeping per-cell alignment and column widths needs model fields (TableCell.alignment, TableContent.columnWidths) + DOCX/PDF export + DOCX import (tblGrid) - overlaps DOCX-017. | R24: EDIT-005 | S24: AUD-08
A25: EDIT-012 | B25: 1 | C25: EDITOR | D25: Colour and font values outside the model reported | E25: Pasted colours (hsl(), transparent...) and font stacks the model can't hold are normalised or dropped on save without a report. | F25: P3 | G25: DONE | H25: Formatting the editor holds that the model can't keep is named, never dropped silently: colours (hsl(), theme names; transparent is no loss), fonts, sizes (em/%), nested alignment/picture sizes, differing cell alignment, column widths. reconcileWithIds returns notes; the status bar shows 'N formatting changes not kept' (title lists them) and the Проверка panel a 'While editing' section; saving goes on. | I25: frontend/editor/directFormatting.test.ts, frontend/editor/useAutoSave.test.tsx::names formatting it can't keep, frontend/editor/panels/FidelityPanel.test.tsx::lists what the editor holds, frontend/e2e/direct-formatting.spec.ts | J25: frontend/editor | L25: Low | M25: 46292.398 | N25: 46292.399 | O25: 46292.399 | P25: 53c84e4 | R25: EDIT-005 | S25: AUD-01
A26: EDIT-006 | B26: 1 | C26: EDITOR | D26: Pasted rich HTML survives save | E26: Paste from Word/web (lists in cells, lists in quotes, code in items, images in cells) persists after reload. | F26: P0 | G26: DONE | H26: frontend/e2e/nested.spec.ts: real paste event with text/html in Edge | I26: npx playwright test e2e/nested.spec.ts -> 1 passed | J26: frontend/editor | K26: EDIT-005 | L26: High | M26: 46292.193 | N26: 46292.197 | O26: 46292.197 | P26: 1fe27a9 | S26: AUD-01
A27: EDIT-007 | B27: 1 | C27: EDITOR | D27: Canonical mark order | E27: No spurious save on open when backend and editor order marks differently. | F27: P2 | G27: DONE | H27: Probe confirmed: a run with [bold, italic, link, textStyle] came back from the editor in its schema order (link, textStyle, bold, italic) -> sameContent false -> a save just for opening. Now one order everywhere: the model sorts a run's marks into MarkType order on validation (InlineRun._canonical_order), the editor sorts what it reads (MARK_ORDER), a test pins MARK_ORDER to the generated OpenAPI enum. Golden fixtures unchanged (the importer already wrote this order). | I27: frontend/editor/directFormatting.test.ts (the order of a run's marks: 2; fails without the fix), tests/test_document_nesting.py::test_a_runs_marks_are_kept_in_one_order_whoever_wrote_them | J27: frontend/editor | L27: Low | M27: 46292.409 | N27: 46292.416 | O27: 46292.416 | P27: 66bbdf1 | S27: AUD-16
A28: DOCX-001 | B28: 1 | C28: DOCX | D28: DOCX export of nested blocks | E28: Lists, images, code, nested tables in cells; blocks in list items; quote children. | F28: P0 | G28: DONE | H28: export/docx_export.py: adders write into a _Place (body or cell, indent, width); cells render their blocks; list item blocks under the item text; nested lists one level deeper with own numbering; quote children; numbering start/format via startOverride + per-level numFmt; picture alt text/title (docPr descr/title) | I28: tests/test_nested_blocks_api.py::test_the_word_export_keeps_every_nested_block, ::test_the_word_export_numbers_a_list_from_its_start_in_its_format; existing DOCX suites green | J28: backend/export | K28: CORE-003 | L28: High | M28: 46292.19 | N28: 46292.197 | O28: 46292.197 | P28: 1fe27a9 | S28: AUD-01
A29: PDF-001 | B29: 1 | C29: PDF | D29: PDF export of nested blocks | E29: Same content in the PDF exporter. | F29: P0 | G29: DONE | H29: export/pdf_export.py: cells with blocks become flowable lists sized to the cell; list item/quote blocks indented; numbering start/format with the same level sequence as the Word export (decimal, a, i) | I29: tests/test_nested_blocks_api.py::test_the_pdf_export_keeps_every_nested_block ('v. fifth', 'vi. sixth'); existing PDF suites green | J29: backend/export | K29: CORE-003 | L29: Medium | M29: 46292.19 | N29: 46292.197 | O29: 46292.197 | P29: 1fe27a9 | S29: AUD-01
A30: FID-001 | B30: 1 | C30: FIDELITY | D30: Structured Document Fidelity Report | E30: fidelityReport items: element, feature, source state, new state, confidence, reason, class (policy classes). | F30: P0 | G30: DONE | H30: backend/app/fidelity/{report,content,docx_source,text_sources,imports}.py; Document.importReport; ingestion_service attaches it for DOCX, PDF, .txt and paste | I30: tests/test_fidelity_report.py (29); calibration: 29 Word/golden fixtures verified except the genuine a03 heading-number change | J30: backend/models | L30: Medium | M30: 46292.218 | N30: 46292.219 | O30: 46292.219 | P30: 8a330be | S30: AUD-03
A31: FID-002 | B31: 1 | C31: FIDELITY | D31: Importer reports every detected change | E31: Hidden text, caps, underline variants, numbering formats/continuation, sections, header variants, content controls, custom properties, links dropped, crop/rotation, table geometry, bullets in cells, empty paragraphs, autolinks, SmartArt/charts. | F31: P0 | G31: DONE | H31: Importer names every change it makes without keeping: hidden text, caps, underline variants, content controls, custom properties + sensitivity labels (values never echoed), crop/rotation, table geometry, bullets in cells, RTL, autolinks, charts/SmartArt/shapes (app/fidelity/docx_detect.py on the file itself, with an example of the text); numbering labels/multi-level/empty items + numbered headings (parsers/docx.py); empty spacing paragraphs; links with unsafe addresses kept as text (docx_inline._safe); sections: page setup per section, odd/even breaks, page-number restarts/styles, page borders, line numbers, vertical alignment. Header/footer variants already caught by the header/footer word check. | I31: tests/test_docx_detect.py (9 tests), tests/test_docx_numbering.py (5), tests/test_capabilities.py (6), tests/test_fidelity_report.py; full backend 713 passed/1 skipped; Vitest 84 passed; tsc + eslint clean | J31: backend/parsers | K31: FID-001 | L31: High | M31: 46292.218 | N31: 46292.376 | O31: 46292.376 | P31: 622d9c1 | Q31: Done: all existing importer notes structured; content check catches any word loss; header/footer text loss detected. Open: explicit detections for hidden text, caps, underline variants, numbering formats/continuation/start, sections, content controls, custom properties, dropped links, crop/rotation, table geometry, bullets in cells, empty paragraphs, autolinks, SmartArt/charts. | R31: FID-001 | S31: AUD-03,AUD-04,AUD-06,AUD-07,AUD-08
A32: FID-003 | B32: 1 | C32: FIDELITY | D32: Export fidelity report | E32: What an export changes or drops is reported the same way. | F32: P0 | G32: DONE | H32: backend/app/fidelity/exports.py (collecting/note, pdf_document_notes, export_report); docx_export/pdf_export record what they approximate or drop; export job result carries 'fidelity'; frontend ExportMenu ExportResult; PDF alt-text note | I32: tests/test_export_fidelity.py (6), tests/test_jobs.py; editor/ExportResult.test.tsx (4); e2e documents.spec.ts export test checks the message; calibration: DOCX export re-reads identically on 29 fixtures, PDF on all but a11-multilingual (genuine) | J32: backend/export | K32: FID-001 | L32: Medium | M32: 46292.35 | N32: 46292.351 | O32: 46292.351 | P32: e55412f | R32: FID-001 | S32: AUD-03,AUD-18
A33: FID-004 | B33: 1 | C33: FIDELITY | D33: Content protection UI | E33: Report panel + badge: 'No content changes' only when proven; otherwise 'N items require review'. | F33: P0 | G33: DONE | H33: frontend/editor/panels/FidelityPanel.tsx (Проверка rail panel), EditorStatusBar import badge; 'No content changes' only when the words matched and no item lost content | I33: editor/panels/FidelityPanel.test.tsx (3); e2e/fidelity.spec.ts; checked in a throwaway stack with the audit's a03/a05 fixtures | J33: frontend/editor | K33: FID-002 | L33: Medium | M33: 46292.218 | N33: 46292.219 | O33: 46292.219 | P33: 8a330be | R33: FID-001 | S33: AUD-03
A34: FID-005 | B34: 1 | C34: FIDELITY | D34: Unsupported-feature policy classes | E34: NOT_DETECTED, DETECTED_PRESERVED, DETECTED_NOT_EDITABLE, LOSSY, UNSUPPORTED, BLOCKED on every report item. | F34: P0 | G34: DONE | H34: app/fidelity/report.py FidelityPolicy (not_detected, detected_preserved, detected_not_editable, lossy, unsupported, blocked); every DOCX importer note classified (docx_inline.Notes, docx.py) | I34: tests/test_fidelity_report.py | J34: backend/models | K34: FID-001 | L34: Low | M34: 46292.218 | N34: 46292.219 | O34: 46292.219 | P34: 8a330be | R34: FID-001 | S34: AUD-03
A35: CORE-004 | B35: 1 | C35: CORE | D35: Machine-readable capability matrix | E35: DOCX/PDF/editor capabilities (import/edit/export/round_trip) as data; served by the API; drives badges, warnings, tests. | F35: P1 | G35: DONE | H35: backend/app/capabilities.py (67 features across Word, PDF, editor, text: import/edit/export/roundTrip + policy + report keys + tests + notes naming the task for every unreported gap); GET /api/v1/capabilities (public) | I35: tests/test_capabilities.py (6): every reported key described and every described key reported, cited tests exist, no round trip 'yes' without a test, gaps name their task, API | J35: backend/capabilities | K35: FID-005 | L35: Low | M35: 46292.357 | N35: 46292.358 | O35: 46292.358 | P35: fcf30d7 | Q35: UI use (badges, pre-export warnings) comes with REV-002/FID-004 follow-ups. | S35: AUD-20
A36: TEST-010 | B36: 1 | C36: TESTING | D36: Regression tests for nested structures | E36: Backend unit/API, Vitest mapping, Playwright paste + reload. | F36: P0 | G36: DONE | H36: Nested structures covered at every layer and green: model (tests/test_document_nesting.py), API + storage + exports (tests/test_nested_blocks_api.py), editor mapping both ways (frontend/editor/nestedBlocks.test.ts), paste -> save -> reload in a real browser (frontend/e2e/nested.spec.ts); plus the golden round trip (editorRoundTrip.test.ts) and direct formatting (directFormatting.test.ts, e2e/direct-formatting.spec.ts). | I36: backend 753 passed; Vitest 113; Playwright 19 | J36: tests | K36: EDIT-006,DOCX-001 | L36: Medium | M36: 46292.193 | N36: 46292.416 | O36: 46292.416 | P36: 66bbdf1 | S36: AUD-01
A37: INFRA-005 | B37: 1 | C37: INFRA | D37: Throwaway preview stack for browser checks | E37: tools/dev/throwaway-backend.ps1 (fresh SQLite, never the real DB) and throwaway-frontend.ps1 (:3100 against :8100); launch configs. | F37: P2 | G37: DONE | H37: tools/dev/throwaway-*.ps1, .claude/launch.json backend-throwaway/frontend-throwaway, frontend/.gitignore + eslint/vitest ignore .next-preview | I37: Used for the FID-004 browser check (a03/a05 uploads) | J37: tools/dev | L37: Low | M37: 46292.218 | N37: 46292.219 | O37: 46292.219 | P37: 8a330be
A38: FID-006 | B38: 1 | C38: FIDELITY | D38: Text imports name what Markdown can't bring in | E38: Pasted/.txt Markdown dropped pictures (and their descriptions) and thematic breaks without a word, while the content check said verified (alt text isn't body text). | F38: P1 | G38: DONE | H38: parse_markdown attaches an import report: pictures -> markdown.image (UNSUPPORTED, contentChanged, count, example description) so the verdict is 'Body text complete, some content left out'; not fetched on purpose (server-side fetch of any address). '---' is now a horizontal rule element. Raw HTML stays literal text (html=False), no words lost (probed). Matrix rows text.markdown + text.markdown_images; capability key pattern knows 'markdown.'. | I38: tests/test_markdown_parser.py::test_a_thematic_break_is_a_horizontal_rule, tests/test_markdown_parser.py::test_pictures_are_named_as_left_out_not_dropped_silently, tests/test_capabilities.py | J38: backend/parsers | K38: FID-001 | L38: Medium | M38: 46292.407 | N38: 46292.416 | O38: 46292.416 | P38: 66bbdf1 | Q38: Found 2026-09-27 during EDIT-010 (probe: '![chart](url)' -> 'See below.', status verified, no items).
A39: AI-001 | B39: 2 | C39: AI | D39: Content fidelity comparator | E39: Order-, count-, token-, numeric-, punctuation- and structure-aware diff of source vs AI output. | F39: P0 | G39: DONE | H39: app/fidelity/text_check.py: check_text compares source and AI answer token by token in order (words; numbers with sign/decimals/separators/percent as one token; every punctuation mark); verified only when identical after removing what isn't content (spacing, typographic variants, table separators, list/heading marks at line starts). Differences classified number/unit/negation/sentence/duplicate/reordered/punctuation/words; moved runs paired by their words. Replaces the bag-of-words 20%-unknown check (AUD-02) that passed sentence deletions, 'not' removal and 5->50. | I39: tests/test_ai_fidelity.py (36) | J39: backend/ai | L39: High | M39: 46292.218 | N39: 46292.606 | O39: 46292.606 | P39: 78f5c8f | Q39: compare_words (app/fidelity/content.py): order/count/token-aware, numbers and negation caught, moved passages told apart; used by the import report. Phase 2: punctuation/structure awareness, use inside structure analysis. | S39: AUD-02
A40: AI-002 | B40: 2 | C40: AI | D40: Protected facts: numbers, units, percentages, dates, identifiers | E40: 5 mg never becomes 50 mg without explicit user action. | F40: P0 | G40: DONE | H40: Numbers (amounts, percentages incl. decimal separator, dates, times, identifiers with digits) and units after a number are protected facts: a difference touching one is protected (TextDifference.protected; a reordered one isn't). Structure analysis refuses any change; text_check.changed_numbers(source, result) names lost/gained numbers where words may rightly differ (translation, requested rewording). | I40: tests/test_ai_fidelity.py (alteration cases with protected flags; test_numbers_are_facts_even_where_the_words_may_change) | J40: backend/ai | K40: AI-001 | L40: High | M40: 46292.606 | N40: 46292.606 | O40: 46292.606 | P40: 78f5c8f | Q40: Translation (TRAN-*) and AI proposals (AI-006) use changed_numbers / protected. | R40: AI-001 | S40: AUD-02
...

Sheet CRITICAL_FIXES
A1: CRITICAL_FIXES — Audit findings and P0 tasks
A2: The 20 findings of the 2026-09-26 audit (current known risks) with fix progress, then every P0 task. Report: https://claude.ai/artifact/WKskiyexTDLAHe1BfjvWR1 — a finding is RESOLVED when every linked fix task is DONE.
A3: Findings | B3: Resolved | C3: In progress | D3: Blocked | E3: Open | F3: P0 tasks | G3: P0 done | H3: P0 remaining
A4: =COUNTA(A8:A27) -> 20 | B4: =COUNTIF(B8:B27,"RESOLVED") -> 19 | C4: =COUNTIF(B8:B27,"IN_PROGRESS") -> 0 | D4: =COUNTIF(B8:B27,"BLOCKED") -> 1 | E4: =COUNTIF(B8:B27,"OPEN") -> 0 | F4: =COUNTIF(MASTER!$F$2:$F$2000,"P0") -> 97 | G4: =COUNTIFS(MASTER!$F$2:$F$2000,"P0",MASTER!$G$2:$G$2000,"DONE") -> 88 | H4: =F4-G4 -> 9
A6: Audit findings (current known risks)
A7: Finding ID | B7: Status | C7: Progress | D7: Finding | E7: Tasks | F7: Done | G7: Fix Tasks | H7: Active | I7: Blocked/Failed | J7: Notes
A8: AUD-01 | B8: =IF(E8=0,"OPEN",IF(F8=E8,"RESOLVED",IF(I8>0,"BLOCKED",IF(H8+F8>0,"IN_PROGRESS","OPEN")))) -> RESOLVED | C8: =IF(E8=0,0,F8/E8) -> 1 | D8: Editor save can discard nested blocks (lists, pictures, code, quotes inside cells/items) | E8: =IF(LEN(SUBSTITUTE($G8," ",""))=0,0,LEN(SUBSTITUTE($G8," ",""))-LEN(SUBSTITUTE(SUBSTITUTE($G8," ",""),",",""))+1) -> 5 | F8: =SUMPRODUCT(ISNUMBER(SEARCH(","&MASTER!$A$2:$A$2000&",",","&SUBSTITUTE($G8," ","")&","))*((MASTER!$G$2:$G$2000="DONE"))) -> 5 | G8: EDIT-001,EDIT-002,EDIT-003,EDIT-005,EDIT-006 | H8: =SUMPRODUCT(ISNUMBER(SEARCH(","&MASTER!$A$2:$A$2000&",",","&SUBSTITUTE($G8," ","")&","))*((MASTER!$G$2:$G$2000="IN_PROGRESS")+(MASTER!$G$2:$G$2000="IMPLEMENTED")+(MASTER!$G$2:$G$2000="TESTING")+(MASTER!$G$2:$G$2000="VERIFIED"))) -> 0 | I8: =SUMPRODUCT(ISNUMBER(SEARCH(","&MASTER!$A$2:$A$2000&",",","&SUBSTITUTE($G8," ","")&","))*((MASTER!$G$2:$G$2000="BLOCKED")+(MASTER!$G$2:$G$2000="FAILED"))) -> 0
A9: AUD-02 | B9: =IF(E9=0,"OPEN",IF(F9=E9,"RESOLVED",IF(I9>0,"BLOCKED",IF(H9+F9>0,"IN_PROGRESS","OPEN")))) -> RESOLVED | C9: =IF(E9=0,0,F9/E9) -> 1 | D9: AI fidelity check misses omissions, negation removal, number changes, inserted text | E9: =IF(LEN(SUBSTITUTE($G9," ",""))=0,0,LEN(SUBSTITUTE($G9," ",""))-LEN(SUBSTITUTE(SUBSTITUTE($G9," ",""),",",""))+1) -> 4 | F9: =SUMPRODUCT(ISNUMBER(SEARCH(","&MASTER!$A$2:$A$2000&",",","&SUBSTITUTE($G9," ","")&","))*((MASTER!$G$2:$G$2000="DONE"))) -> 4 | G9: AI-001,AI-002,AI-003,AI-004 | H9: =SUMPRODUCT(ISNUMBER(SEARCH(","&MASTER!$A$2:$A$2000&",",","&SUBSTITUTE($G9," ","")&","))*((MASTER!$G$2:$G$2000="IN_PROGRESS")+(MASTER!$G$2:$G$2000="IMPLEMENTED")+(MASTER!$G$2:$G$2000="TESTING")+(MASTER!$G$2:$G$2000="VERIFIED"))) -> 0 | I9: =SUMPRODUCT(ISNUMBER(SEARCH(","&MASTER!$A$2:$A$2000&",",","&SUBSTITUTE($G9," ","")&","))*((MASTER!$G$2:$G$2000="BLOCKED")+(MASTER!$G$2:$G$2000="FAILED"))) -> 0 | J9: Fixed in Phase 2 (AI-001..004): AI structure answers are checked token by token; any omission, negation removal, number/unit/date change, insertion, reordering, duplication or punctuation change is refused.
A10: AUD-03 | B10: =IF(E10=0,"OPEN",IF(F10=E10,"RESOLVED",IF(I10>0,"BLOCKED",IF(H10+F10>0,"IN_PROGRESS","OPEN")))) -> RESOLVED | C10: =IF(E10=0,0,F10/E10) -> 1 | D10: Import/export silently changes hidden text, numbering, section headers, metadata, alt text, structure | E10: =IF(LEN(SUBSTITUTE($G10," ",""))=0,0,LEN(SUBSTITUTE($G10," ",""))-LEN(SUBSTITUTE(SUBSTITUTE($G10," ",""),",",""))+1) -> 5 | F10: =SUMPRODUCT(ISNUMBER(SEARCH(","&MASTER!$A$2:$A$2000&",",","&SUBSTITUTE($G10," ","")&","))*((MASTER!$G$2:$G$2000="DONE"))) -> 5 | G10: FID-002,DOCX-011,DOCX-013,DOCX-015,DOCX-025 | H10: =SUMPRODUCT(ISNUMBER(SEARCH(","&MASTER!$A$2:$A$2000&",",","&SUBSTITUTE($G10," ","")&","))*((MASTER!$G$2:$G$2000="IN_PROGRESS")+(MASTER!$G$2:$G$2000="IMPLEMENTED")+(MASTER!$G$2:$G$2000="TESTING")+(MASTER!$G$2:$G$2000="VERIFIED"))) -> 0 | I10: =SUMPRODUCT(ISNUMBER(SEARCH(","&MASTER!$A$2:$A$2000&",",","&SUBSTITUTE($G10," ","")&","))*((MASTER!$G$2:$G$2000="BLOCKED")+(MASTER!$G$2:$G$2000="FAILED"))) -> 0
A11: AUD-04 | B11: =IF(E11=0,"OPEN",IF(F11=E11,"RESOLVED",IF(I11>0,"BLOCKED",IF(H11+F11>0,"IN_PROGRESS","OPEN")))) -> RESOLVED | C11: =IF(E11=0,0,F11/E11) -> 1 | D11: List numbering changes ('Чл. 1.' -> '1.', '(a)' -> 'a.', start values) | E11: =IF(LEN(SUBSTITUTE($G11," ",""))=0,0,LEN(SUBSTITUTE($G11," ",""))-LEN(SUBSTITUTE(SUBSTITUTE($G11," ",""),",",""))+1) -> 1 | F11: =SUMPRODUCT(ISNUMBER(SEARCH(","&MASTER!$A$2:$A$2000&",",","&SUBSTITUTE($G11," ","")&","))*((MASTER!$G$2:$G$2000="DONE"))) -> 1 | G11: DOCX-016 | H11: =SUMPRODUCT(ISNUMBER(SEARCH(","&MASTER!$A$2:$A$2000&",",","&SUBSTITUTE($G11," ","")&","))*((MASTER!$G$2:$G$2000="IN_PROGRESS")+(MASTER!$G$2:$G$2000="IMPLEMENTED")+(MASTER!$G$2:$G$2000="TESTING")+(MASTER!$G$2:$G$2000="VERIFIED"))) -> 0 | I11: =SUMPRODUCT(ISNUMBER(SEARCH(","&MASTER!$A$2:$A$2000&",",","&SUBSTITUTE($G11," ","")&","))*((MASTER!$G$2:$G$2000="BLOCKED")+(MASTER!$G$2:$G$2000="FAILED"))) -> 0 | J11: Partly fixed in 622d9c1: list format/start/continuation kept; custom labels ('Чл. 1.', '(a)') and multi-level labels reported, not kept yet (DOCX-016).
A12: AUD-05 | B12: =IF(E12=0,"OPEN",IF(F12=E12,"RESOLVED",IF(I12>0,"BLOCKED",IF(H12+F12>0,"IN_PROGRESS","OPEN")))) -> RESOLVED | C12: =IF(E12=0,0,F12/E12) -> 1 | D12: AI instruction operations can delete/insert/move content without preview | E12: =IF(LEN(SUBSTITUTE($G12," ",""))=0,0,LEN(SUBSTITUTE($G12," ",""))-LEN(SUBSTITUTE(SUBSTITUTE($G12," ",""),",",""))+1) -> 4 | F12: =SUMPRODUCT(ISNUMBER(SEARCH(","&MASTER!$A$2:$A$2000&",",","&SUBSTITUTE($G12," ","")&","))*((MASTER!$G$2:$G$2000="DONE"))) -> 4 | G12: AI-005,AI-006,AI-007,REV-003 | H12: =SUMPRODUCT(ISNUMBER(SEARCH(","&MASTER!$A$2:$A$2000&",",","&SUBSTITUTE($G12," ","")&","))*((MASTER!$G$2:$G$2000="IN_PROGRESS")+(MASTER!$G$2:$G$2000="IMPLEMENTED")+(MASTER!$G$2:$G$2000="TESTING")+(MASTER!$G$2:$G$2000="VERIFIED"))) -> 0 | I12: =SUMPRODUCT(ISNUMBER(SEARCH(","&MASTER!$A$2:$A$2000&",",","&SUBSTITUTE($G12," ","")&","))*((MASTER!$G$2:$G$2000="BLOCKED")+(MASTER!$G$2:$G$2000="FAILED"))) -> 0 | J12: Fixed in Phase 2 (AI-005..AI-007: content operations become proposals) and enforced server-side in Phase 14 (REV-003, ed68af3): nothing but accepting a proposal can insert, delete or move content.
A13: AUD-06 | B13: =IF(E13=0,"OPEN",IF(F13=E13,"RESOLVED",IF(I13>0,"BLOCKED",IF(H13+F13>0,"IN_PROGRESS","OPEN")))) -> RESOLVED | C13: =IF(E13=0,0,F13/E13) -> 1 | D13: Content controls, metadata, comment threads, sensitivity information lost | E13: =IF(LEN(SUBSTITUTE($G13," ",""))=0,0,LEN(SUBSTITUTE($G13," ",""))-LEN(SUBSTITUTE(SUBSTITUTE($G13," ",""),",",""))+1) -> 3 | F13: =SUMPRODUCT(ISNUMBER(SEARCH(","&MASTER!$A$2:$A$2000&",",","&SUBSTITUTE($G13," ","")&","))*((MASTER!$G$2:$G$2000="DONE"))) -> 3 | G13: DOCX-012,DOCX-021,DOCX-023 | H13: =SUMPRODUCT(ISNUMBER(SEARCH(","&MASTER!$A$2:$A$2000&",",","&SUBSTITUTE($G13," ","")&","))*((MASTER!$G$2:$G$2000="IN_PROGRESS")+(MASTER!$G$2:$G$2000="IMPLEMENTED")+(MASTER!$G$2:$G$2000="TESTING")+(MASTER!$G$2:$G$2000="VERIFIED"))) -> 0 | I13: =SUMPRODUCT(ISNUMBER(SEARCH(","&MASTER!$A$2:$A$2000&",",","&SUBSTITUTE($G13," ","")&","))*((MASTER!$G$2:$G$2000="BLOCKED")+(MASTER!$G$2:$G$2000="FAILED"))) -> 0
A14: AUD-07 | B14: =IF(E14=0,"OPEN",IF(F14=E14,"RESOLVED",IF(I14>0,"BLOCKED",IF(H14+F14>0,"IN_PROGRESS","OPEN")))) -> RESOLVED | C14: =IF(E14=0,0,F14/E14) -> 1 | D14: Image fidelity gaps: alt text, crop, rotation, formats | E14: =IF(LEN(SUBSTITUTE($G14," ",""))=0,0,LEN(SUBSTITUTE($G14," ",""))-LEN(SUBSTITUTE(SUBSTITUTE($G14," ",""),",",""))+1) -> 1 | F14: =SUMPRODUCT(ISNUMBER(SEARCH(","&MASTER!$A$2:$A$2000&",",","&SUBSTITUTE($G14," ","")&","))*((MASTER!$G$2:$G$2000="DONE"))) -> 1 | G14: DOCX-018 | H14: =SUMPRODUCT(ISNUMBER(SEARCH(","&MASTER!$A$2:$A$2000&",",","&SUBSTITUTE($G14," ","")&","))*((MASTER!$G$2:$G$2000="IN_PROGRESS")+(MASTER!$G$2:$G$2000="IMPLEMENTED")+(MASTER!$G$2:$G$2000="TESTING")+(MASTER!$G$2:$G$2000="VERIFIED"))) -> 0 | I14: =SUMPRODUCT(ISNUMBER(SEARCH(","&MASTER!$A$2:$A$2000&",",","&SUBSTITUTE($G14," ","")&","))*((MASTER!$G$2:$G$2000="BLOCKED")+(MASTER!$G$2:$G$2000="FAILED"))) -> 0
A15: AUD-08 | B15: =IF(E15=0,"OPEN",IF(F15=E15,"RESOLVED",IF(I15>0,"BLOCKED",IF(H15+F15>0,"IN_PROGRESS","OPEN")))) -> RESOLVED | C15: =IF(E15=0,0,F15/E15) -> 1 | D15: Table export changes header state, borders, alignment, widths, geometry | E15: =IF(LEN(SUBSTITUTE($G15," ",""))=0,0,LEN(SUBSTITUTE($G15," ",""))-LEN(SUBSTITUTE(SUBSTITUTE($G15," ",""),",",""))+1) -> 1 | F15: =SUMPRODUCT(ISNUMBER(SEARCH(","&MASTER!$A$2:$A$2000&",",","&SUBSTITUTE($G15," ","")&","))*((MASTER!$G$2:$G$2000="DONE"))) -> 1 | G15: DOCX-017 | H15: =SUMPRODUCT(ISNUMBER(SEARCH(","&MASTER!$A$2:$A$2000&",",","&SUBSTITUTE($G15," ","")&","))*((MASTER!$G$2:$G$2000="IN_PROGRESS")+(MASTER!$G$2:$G$2000="IMPLEMENTED")+(MASTER!$G$2:$G$2000="TESTING")+(MASTER!$G$2:$G$2000="VERIFIED"))) -> 0 | I15: =SUMPRODUCT(ISNUMBER(SEARCH(","&MASTER!$A$2:$A$2000&",",","&SUBSTITUTE($G15," ","")&","))*((MASTER!$G$2:$G$2000="BLOCKED")+(MASTER!$G$2:$G$2000="FAILED"))) -> 0
A16: AUD-09 | B16: =IF(E16=0,"OPEN",IF(F16=E16,"RESOLVED",IF(I16>0,"BLOCKED",IF(H16+F16>0,"IN_PROGRESS","OPEN")))) -> RESOLVED | C16: =IF(E16=0,0,F16/E16) -> 1 | D16: Large images cause huge memory consumption | E16: =IF(LEN(SUBSTITUTE($G16," ",""))=0,0,LEN(SUBSTITUTE($G16," ",""))-LEN(SUBSTITUTE(SUBSTITUTE($G16," ",""),",",""))+1) -> 2 | F16: =SUMPRODUCT(ISNUMBER(SEARCH(","&MASTER!$A$2:$A$2000&",",","&SUBSTITUTE($G16," ","")&","))*((MASTER!$G$2:$G$2000="DONE"))) -> 2 | G16: SEC-012,SEC-013 | H16: =SUMPRODUCT(ISNUMBER(SEARCH(","&MASTER!$A$2:$A$2000&",",","&SUBSTITUTE($G16," ","")&","))*((MASTER!$G$2:$G$2000="IN_PROGRESS")+(MASTER!$G$2:$G$2000="IMPLEMENTED")+(MASTER!$G$2:$G$2000="TESTING")+(MASTER!$G$2:$G$2000="VERIFIED"))) -> 0 | I16: =SUMPRODUCT(ISNUMBER(SEARCH(","&MASTER!$A$2:$A$2000&",",","&SUBSTITUTE($G16," ","")&","))*((MASTER!$G$2:$G$2000="BLOCKED")+(MASTER!$G$2:$G$2000="FAILED"))) -> 0
A17: AUD-10 | B17: =IF(E17=0,"OPEN",IF(F17=E17,"RESOLVED",IF(I17>0,"BLOCKED",IF(H17+F17>0,"IN_PROGRESS","OPEN")))) -> RESOLVED | C17: =IF(E17=0,0,F17/E17) -> 1 | D17: Large tables have a performance problem | E17: =IF(LEN(SUBSTITUTE($G17," ",""))=0,0,LEN(SUBSTITUTE($G17," ",""))-LEN(SUBSTITUTE(SUBSTITUTE($G17," ",""),",",""))+1) -> 1 | F17: =SUMPRODUCT(ISNUMBER(SEARCH(","&MASTER!$A$2:$A$2000&",",","&SUBSTITUTE($G17," ","")&","))*((MASTER!$G$2:$G$2000="DONE"))) -> 1 | G17: PERF-001 | H17: =SUMPRODUCT(ISNUMBER(SEARCH(","&MASTER!$A$2:$A$2000&",",","&SUBSTITUTE($G17," ","")&","))*((MASTER!$G$2:$G$2000="IN_PROGRESS")+(MASTER!$G$2:$G$2000="IMPLEMENTED")+(MASTER!$G$2:$G$2000="TESTING")+(MASTER!$G$2:$G$2000="VERIFIED"))) -> 0 | I17: =SUMPRODUCT(ISNUMBER(SEARCH(","&MASTER!$A$2:$A$2000&",",","&SUBSTITUTE($G17," ","")&","))*((MASTER!$G$2:$G$2000="BLOCKED")+(MASTER!$G$2:$G$2000="FAILED"))) -> 0
